Workbook

Sheet Read_me
A1: HOW TO USE
A2: 1. Edit only blue cells on Assumptions. Yellow fill = assumption that most needs a real number.
A3: 2. Three scenarios run side by side (Model_Cons / Model_Base / Model_Aggr). Summary, Unit_Economics and Sensitivity update automatically.
A4: 3. Months are counted from launch. Calendar mapping uses 'Calendar month of launch' for seasonality only.
A6: STRUCTURE
A7: Funnel -> cohort survivors -> AUM (deposits, exits, partial withdrawals) -> revenue -> bonus cost -> costs -> net contribution.
A8: Counterfactual rows re-run AUM without Pause & Reflect to size AUM retained.
A10: SIMPLIFICATIONS (be honest about them)
A11: - Constant monthly churn; one average balance for all users; no discounting; no compounding of bonus interest.
A12: - Bonus interest is paid on all Habitlock savings balances, but only 'incrementality' of revenue is counted as new.
A13: - Badge levels follow deck unlock rules by tenure; Lv5 and Lv6 depend on auto-invest adoption after AI launch.
A14: - All take rates, CAC, retention and balances are illustrative. Replace with Infina data before using any output.
A16: COLOUR CODE: blue input, black formula, green link to another sheet, yellow fill = key assumption.

Sheet Summary
A1: Habitlock financial model: summary
A2: 18 months from launch. VND. Every input is illustrative unless the Assumptions tab says 'Deck'. This is a reasoning tool, not a forecast.
A4: Metric | B4: Unit | C4: Conservative | D4: Base | E4: Aggressive
A5: Scale
A6: Users acquired, cumulative M18 | B6: users | C6: =Model_Cons!U13 -> 150000 | D6: =Model_Base!U13 -> 300000 | E6: =Model_Aggr!U13 -> 600000
A7: Activated users (first deposit), cumulative | B7: users | C7: =Model_Cons!C10 -> 75000 | D7: =Model_Base!C10 -> 180000 | E7: =Model_Aggr!C10 -> 420000
A8: Active users, M18 | B8: users | C8: =Model_Cons!U11 -> 30693.461 | D8: =Model_Base!U11 -> 96828.953 | E8: =Model_Aggr!U11 -> 281987.78
A9: AUM, M18 | B9: VND bn | C9: =Model_Cons!U21/1000 -> 48.707519 | D9: =Model_Base!U21/1000 -> 298.58156 | E9: =Model_Aggr!U21/1000 -> 1584.7798
A10: Average balance per active user, M18 | B10: VND mn | C10: =Model_Cons!U21/Model_Cons!U11 -> 1.5869022 | D10: =Model_Base!U21/Model_Base!U11 -> 3.083598 | E10: =Model_Aggr!U21/Model_Aggr!U11 -> 5.6200303
A11: AUM retained thanks to Pause & Reflect, M18 | B11: VND bn | C11: =Model_Cons!U31/1000 -> 0.69851615 | D11: =Model_Base!U31/1000 -> 7.8733198 | E11: =Model_Aggr!U31/1000 -> 62.809597
A12: P&L, 18 months, VND mn
A13: Incremental revenue | B13: VND mn | C13: =Model_Cons!C36 -> 56.309089 | D13: =Model_Base!C36 -> 721.2107 | E13: =Model_Aggr!C36 -> 6330.0942
A14: Bonus interest cost | B14: VND mn | C14: =Model_Cons!C38 -> 32.438328 | D14: =Model_Base!C38 -> 233.83508 | E14: =Model_Aggr!C38 -> 1315.3696
A15: Bonus cost as % of incremental revenue | B15: % | C15: =IF(C13>0,C14/C13,0) -> 0.57607624 | D15: =IF(D13>0,D14/D13,0) -> 0.32422575 | E15: =IF(E13>0,E14/E13,0) -> 0.20779621
A16: Acquisition spend | B16: VND mn | C16: =Model_Cons!C39 -> 15000 | D16: =Model_Base!C39 -> 21600 | E16: =Model_Aggr!C39 -> 33600
A17: Build + run cost | B17: VND mn | C17: =Model_Cons!C40+Model_Cons!C41 -> 3660 | D17: =Model_Base!C40+Model_Base!C41 -> 3660 | E17: =Model_Aggr!C40+Model_Aggr!C41 -> 3660
A18: Cumulative net contribution, M18 | B18: VND mn | C18: =Model_Cons!U43 -> -18636.129 | D18: =Model_Base!U43 -> -24772.624 | E18: =Model_Aggr!U43 -> -32245.275
A19: First month cumulative net >= 0 | B19: month | C19: =IFERROR(MATCH(1,Model_Cons!D44:U44,0),"Not within 18M") -> Not within 18M | D19: =IFERROR(MATCH(1,Model_Base!D44:U44,0),"Not within 18M") -> Not within 18M | E19: =IFERROR(MATCH(1,Model_Aggr!D44:U44,0),"Not within 18M") -> Not within 18M
A20: First month monthly net >= 0 | B20: month | C20: =IFERROR(MATCH(1,Model_Cons!D45:U45,0),"Not within 18M") -> Not within 18M | D20: =IFERROR(MATCH(1,Model_Base!D45:U45,0),"Not within 18M") -> Not within 18M | E20: =IFERROR(MATCH(1,Model_Aggr!D45:U45,0),"Not within 18M") -> Not within 18M
A21: Cross-checks against the deck
A22: Required P&R effectiveness to hit deck Dec adherence target | B22: % | C22: =(Assumptions!$C$44-Assumptions!$C$43)/(1-Assumptions!$C$43) -> 0.47368421 | D22: =(Assumptions!$D$44-Assumptions!$D$43)/(1-Assumptions!$D$43) -> 0.47368421 | E22: =(Assumptions!$E$44-Assumptions!$E$43)/(1-Assumptions!$E$43) -> 0.47368421
A23: P&R effectiveness assumed in this scenario | B23: % | C23: =Assumptions!$C$22 -> 0.1 | D23: =Assumptions!$D$22 -> 0.2 | E23: =Assumptions!$E$22 -> 0.35
A24: Earliest month any user can reach Lv4 (badge launch + 3) | B24: month | C24: =Assumptions!$C$32+3 -> 7 | D24: =Assumptions!$D$32+3 -> 7 | E24: =Assumptions!$E$32+3 -> 7
A25: Deck Phase 3 (needs Lv4 users) ends in month | B25: month | C25: =Assumptions!$C$34 -> 6 | D25: =Assumptions!$D$34 -> 6 | E25: =Assumptions!$E$34 -> 6
A26: Timeline check | C26: =IF(C24>C25,"CONFLICT: Lv4 arrives after Phase 3","OK") -> CONFLICT: Lv4 arrives after Phase 3 | D26: =IF(D24>D25,"CONFLICT: Lv4 arrives after Phase 3","OK") -> CONFLICT: Lv4 arrives after Phase 3 | E26: =IF(E24>E25,"CONFLICT: Lv4 arrives after Phase 3","OK") -> CONFLICT: Lv4 arrives after Phase 3
A27: Share of 'ready' pool reached by M18 (deck claims 20-30%) | B27: % | C27: =Assumptions!$C$14 -> 0.05 | D27: =Assumptions!$D$14 -> 0.1 | E27: =Assumptions!$E$14 -> 0.2
A28: Model integrity checks
A29: Activated users = reach x pool x activation | B29: check | C29: =IF(ABS(Model_Cons!C10-Assumptions!$C$14*Assumptions!$C$12*Assumptions!$C$15)<1,"OK","ERROR") -> OK | D29: =IF(ABS(Model_Base!C10-Assumptions!$D$14*Assumptions!$D$12*Assumptions!$D$15)<1,"OK","ERROR") -> OK | E29: =IF(ABS(Model_Aggr!C10-Assumptions!$E$14*Assumptions!$E$12*Assumptions!$E$15)<1,"OK","ERROR") -> OK
A30: AUM never negative | B30: check | C30: =IF(MIN(Model_Cons!D21:U21)>=0,"OK","ERROR") -> OK | D30: =IF(MIN(Model_Base!D21:U21)>=0,"OK","ERROR") -> OK | E30: =IF(MIN(Model_Aggr!D21:U21)>=0,"OK","ERROR") -> OK
A31: Signup weights sum to 100% | B31: check | C31: =IF(ABS(SUM(Model_Cons!D7:U7)-1)<0.0001,"OK","ERROR") -> OK | D31: =IF(ABS(SUM(Model_Base!D7:U7)-1)<0.0001,"OK","ERROR") -> OK | E31: =IF(ABS(SUM(Model_Aggr!D7:U7)-1)<0.0001,"OK","ERROR") -> OK

Sheet Unit_Economics
A1: Unit economics per active user at M18
A2: Steady-state view using M18 mix. Undiscounted LTV. Take rates and CAC are placeholders: read the ratios as sensitivity, not as a forecast.
A4: Metric | B4: Unit | C4: Conservative | D4: Base | E4: Aggressive
A5: Average balance per active user | B5: VND mn | C5: =Model_Cons!U21/Model_Cons!U11 -> 1.5869022 | D5: =Model_Base!U21/Model_Base!U11 -> 3.083598 | E5: =Model_Aggr!U21/Model_Aggr!U11 -> 5.6200303
A6: Fund share of AUM | B6: % | C6: =Model_Cons!U22 -> 0.05 | D6: =Model_Base!U22 -> 0.1 | E6: =Model_Aggr!U22 -> 0.2
A7: Blended gross take rate | B7: %/yr | C7: =(1-C6)*Assumptions!$C$24+C6*Assumptions!$C$25 -> 0.0031 | D7: =(1-D6)*Assumptions!$D$24+D6*Assumptions!$D$25 -> 0.0053 | E7: =(1-E6)*Assumptions!$E$24+E6*Assumptions!$E$25 -> 0.0076
A8: Incrementality | B8: % | C8: =Assumptions!$C$26 -> 0.5 | D8: =Assumptions!$D$26 -> 0.7 | E8: =Assumptions!$E$26 -> 0.9
A9: Incremental revenue per user per year | B9: VND '000 | C9: =C5*C7*C8*Assumptions!$C$7/Assumptions!$C$8 -> 2.4596983 | D9: =D5*D7*D8*Assumptions!$D$7/Assumptions!$D$8 -> 11.440148 | E9: =E5*E7*E8*Assumptions!$E$7/Assumptions!$E$8 -> 38.441007
A10: Weighted bonus rate on savings | B10: %/yr | C10: =Model_Cons!U37 -> 0.0010670685 | D10: =Model_Base!U37 -> 0.001508751 | E10: =Model_Aggr!U37 -> 0.0019923606
A11: Bonus cost per user per year | B11: VND '000 | C11: =C5*(1-C6)*C10*Assumptions!$C$7/Assumptions!$C$8 -> 1.6086667 | D11: =D5*(1-D6)*D10*Assumptions!$D$7/Assumptions!$D$8 -> 4.1871432 | E11: =E5*(1-E6)*E10*Assumptions!$E$7/Assumptions!$E$8 -> 8.9577014
A12: Net margin per user per year | B12: VND '000 | C12: =C9-C11 -> 0.85103168 | D12: =D9-D11 -> 7.2530052 | E12: =E9-E11 -> 29.483306
A13: Net margin per user per month | B13: VND '000 | C13: =C12/12 -> 0.070919307 | D13: =D12/12 -> 0.6044171 | E13: =E12/12 -> 2.4569421
A14: Expected lifetime (1 / monthly churn) | B14: months | C14: =1/Assumptions!$C$18 -> 8.3333333 | D14: =1/Assumptions!$D$18 -> 12.5 | E14: =1/Assumptions!$E$18 -> 20
A15: LTV (undiscounted) | B15: VND '000 | C15: =C13*C14 -> 0.59099422 | D15: =D13*D14 -> 7.5552138 | E15: =E13*E14 -> 49.138843
A16: CAC per activated user | B16: VND '000 | C16: =Assumptions!$C$16/Assumptions!$C$8 -> 200 | D16: =Assumptions!$D$16/Assumptions!$D$8 -> 120 | E16: =Assumptions!$E$16/Assumptions!$E$8 -> 80
A17: LTV / CAC | B17: x | C17: =IF(C16>0,C15/C16,0) -> 0.0029549711 | D17: =IF(D16>0,D15/D16,0) -> 0.062960115 | E17: =IF(E16>0,E15/E16,0) -> 0.61423553
A18: CAC payback | B18: months | C18: =IF(C13>0,C16/C13,"Never") -> 2820.1065 | D18: =IF(D13>0,D16/D13,"Never") -> 198.53839 | E18: =IF(E13>0,E16/E13,"Never") -> 32.560799
A19: Max sustainable bonus rate (net margin = 0) | B19: %/yr | C19: =IF(C6<1,C7*C8/(1-C6),0) -> 0.0016315789 | D19: =IF(D6<1,D7*D8/(1-D6),0) -> 0.0041222222 | E19: =IF(E6<1,E7*E8/(1-E6),0) -> 0.00855
A20: Headroom: max minus actual bonus rate | B20: %/yr | C20: =C19-C10 -> 0.00056451043 | D20: =D19-D10 -> 0.0026134713 | E20: =E19-E10 -> 0.0065576394
A22: What must be true for the economics to close
A23: Net margin per VND of average AUM (take x incr minus bonus on savings) | B23: %/yr | C23: =C7*C8-(1-C6)*C10 -> 0.00053628491 | D23: =D7*D8-(1-D6)*D10 -> 0.0023521241 | E23: =E7*E8-(1-E6)*E10 -> 0.0052461115
A24: AUM needed just to cover monthly run cost | B24: VND bn | C24: =IF(C23>0,Assumptions!$C$41*12/Assumptions!$C$7/C23/1000,"Never") -> 2685.1399 | D24: =IF(D23>0,Assumptions!$D$41*12/Assumptions!$D$7/D23/1000,"Never") -> 612.21259 | E24: =IF(E23>0,Assumptions!$E$41*12/Assumptions!$E$7/E23/1000,"Never") -> 274.48902
A25: AUM actually reached at M18 | B25: VND bn | C25: =Model_Cons!U21/1000 -> 48.707519 | D25: =Model_Base!U21/1000 -> 298.58156 | E25: =Model_Aggr!U21/1000 -> 1584.7798
A26: M18 AUM as multiple of break-even AUM | B26: x | C26: =IF(ISNUMBER(C24),C25/C24,0) -> 0.018139658 | D26: =IF(ISNUMBER(D24),D25/D24,0) -> 0.48770896 | E26: =IF(ISNUMBER(E24),E25/E24,0) -> 5.7735637
A27: Max CAC for LTV / CAC = 3 | B27: VND '000 | C27: =C15/3 -> 0.19699807 | D27: =D15/3 -> 2.5184046 | E27: =E15/3 -> 16.379614
A28: Avg balance per user needed for LTV / CAC = 3 (current CAC, take rate, churn) | B28: VND mn | C28: =IF(C23>0,3*C16*12/C14/(C23*Assumptions!$C$7/Assumptions!$C$8),"Never") -> 1611.0839 | D28: =IF(D23>0,3*D16*12/D14/(D23*Assumptions!$D$7/Assumptions!$D$8),"Never") -> 146.93102 | E28: =IF(E23>0,3*E16*12/E14/(E23*Assumptions!$E$7/Assumptions!$E$8),"Never") -> 27.448902
A30: Reading guide: if M18 AUM is below break-even AUM, the product does not cover even its own run cost, regardless of CAC. If LTV / CAC < 3, paid acquisition destroys value; the case then depends on organic or partner-funded growth.

Sheet Sensitivity
A1: Sensitivity: does the bonus interest pay for itself?
A2: Table 1 compares each badge's bonus with the net take rate Infina keeps. Table 2 flexes the two biggest unknowns on the Base scenario.
A4: Table 1: spread per VND of savings balance after bonus (incremental take rate minus bonus), annual
A5: Badge | B5: Bonus (annual) | C5: Conservative | D5: Base | E5: Aggressive
A6: =Assumptions!A48&" "&Assumptions!B48 -> Lv1 Saving Rookie | B6: =Assumptions!C48 -> 0.0005 | C6: =Assumptions!$C$24*Assumptions!$C$26-$B6 -> 0.001 | D6: =Assumptions!$D$24*Assumptions!$D$26-$B6 -> 0.003 | E6: =Assumptions!$E$24*Assumptions!$E$26-$B6 -> 0.0058
A7: =Assumptions!A49&" "&Assumptions!B49 -> Lv2 Steady Cash Flow | B7: =Assumptions!C49 -> 0.001 | C7: =Assumptions!$C$24*Assumptions!$C$26-$B7 -> 0.0005 | D7: =Assumptions!$D$24*Assumptions!$D$26-$B7 -> 0.0025 | E7: =Assumptions!$E$24*Assumptions!$E$26-$B7 -> 0.0053
A8: =Assumptions!A50&" "&Assumptions!B50 -> Lv3 Motivation Builder | B8: =Assumptions!C50 -> 0.0015 | C8: =Assumptions!$C$24*Assumptions!$C$26-$B8 -> 0 | D8: =Assumptions!$D$24*Assumptions!$D$26-$B8 -> 0.002 | E8: =Assumptions!$E$24*Assumptions!$E$26-$B8 -> 0.0048
A9: =Assumptions!A51&" "&Assumptions!B51 -> Lv4 Accumulation Master | B9: =Assumptions!C51 -> 0.0025 | C9: =Assumptions!$C$24*Assumptions!$C$26-$B9 -> -0.001 | D9: =Assumptions!$D$24*Assumptions!$D$26-$B9 -> 0.001 | E9: =Assumptions!$E$24*Assumptions!$E$26-$B9 -> 0.0038
A10: =Assumptions!A52&" "&Assumptions!B52 -> Lv5 Habit Investor | B10: =Assumptions!C52 -> 0.003 | C10: =Assumptions!$C$24*Assumptions!$C$26-$B10 -> -0.0015 | D10: =Assumptions!$D$24*Assumptions!$D$26-$B10 -> 0.0005 | E10: =Assumptions!$E$24*Assumptions!$E$26-$B10 -> 0.0033
A11: =Assumptions!A53&" "&Assumptions!B53 -> Lv6 Growth Seeker | B11: =Assumptions!C53 -> 0.004 | C11: =Assumptions!$C$24*Assumptions!$C$26-$B11 -> -0.0025 | D11: =Assumptions!$D$24*Assumptions!$D$26-$B11 -> -0.0005 | E11: =Assumptions!$E$24*Assumptions!$E$26-$B11 -> 0.0023
A12: Negative (red) = a user at that level costs Infina more in bonus than they earn, before CAC and run costs. Bonus is paid on all balances; only the take rate is scaled by incrementality.
A14: Table 2: Base scenario, M18 run-rate annualised net contribution before acquisition spend (VND mn)
A15: Rows: multiplier on take rates. Columns: multiplier on bonus rates.
A16: Take-rate multiplier \ Bonus multiplier | B16: 0.5 | C16: 1 | D16: 1.5 | E16: 2 | F16: 3
A17: 0.5 | B17: =12*(Model_Base!U36*$A17-Model_Base!U38*B$16-Model_Base!U41) -> -1094.8259 | C17: =12*(Model_Base!U36*$A17-Model_Base!U38*C$16-Model_Base!U41) -> -1294.0941 | D17: =12*(Model_Base!U36*$A17-Model_Base!U38*D$16-Model_Base!U41) -> -1493.3623 | E17: =12*(Model_Base!U36*$A17-Model_Base!U38*E$16-Model_Base!U41) -> -1692.6306 | F17: =12*(Model_Base!U36*$A17-Model_Base!U38*F$16-Model_Base!U41) -> -2091.167
A18: 0.75 | B18: =12*(Model_Base!U36*$A18-Model_Base!U38*B$16-Model_Base!U41) -> -822.60471 | C18: =12*(Model_Base!U36*$A18-Model_Base!U38*C$16-Model_Base!U41) -> -1021.8729 | D18: =12*(Model_Base!U36*$A18-Model_Base!U38*D$16-Model_Base!U41) -> -1221.1412 | E18: =12*(Model_Base!U36*$A18-Model_Base!U38*E$16-Model_Base!U41) -> -1420.4094 | F18: =12*(Model_Base!U36*$A18-Model_Base!U38*F$16-Model_Base!U41) -> -1818.9458
A19: 1 | B19: =12*(Model_Base!U36*$A19-Model_Base!U38*B$16-Model_Base!U41) -> -550.38354 | C19: =12*(Model_Base!U36*$A19-Model_Base!U38*C$16-Model_Base!U41) -> -749.65176 | D19: =12*(Model_Base!U36*$A19-Model_Base!U38*D$16-Model_Base!U41) -> -948.91999 | E19: =12*(Model_Base!U36*$A19-Model_Base!U38*E$16-Model_Base!U41) -> -1148.1882 | F19: =12*(Model_Base!U36*$A19-Model_Base!U38*F$16-Model_Base!U41) -> -1546.7247
A20: 1.25 | B20: =12*(Model_Base!U36*$A20-Model_Base!U38*B$16-Model_Base!U41) -> -278.16237 | C20: =12*(Model_Base!U36*$A20-Model_Base!U38*C$16-Model_Base!U41) -> -477.43059 | D20: =12*(Model_Base!U36*$A20-Model_Base!U38*D$16-Model_Base!U41) -> -676.69882 | E20: =12*(Model_Base!U36*$A20-Model_Base!U38*E$16-Model_Base!U41) -> -875.96704 | F20: =12*(Model_Base!U36*$A20-Model_Base!U38*F$16-Model_Base!U41) -> -1274.5035
A21: 1.5 | B21: =12*(Model_Base!U36*$A21-Model_Base!U38*B$16-Model_Base!U41) -> -5.9411938 | C21: =12*(Model_Base!U36*$A21-Model_Base!U38*C$16-Model_Base!U41) -> -205.20942 | D21: =12*(Model_Base!U36*$A21-Model_Base!U38*D$16-Model_Base!U41) -> -404.47764 | E21: =12*(Model_Base!U36*$A21-Model_Base!U38*E$16-Model_Base!U41) -> -603.74587 | F21: =12*(Model_Base!U36*$A21-Model_Base!U38*F$16-Model_Base!U41) -> -1002.2823
A24: Table 3: Base scenario LTV / CAC by CAC (rows) and average balance multiplier (columns)
A25: CAC per activated user in VND thousand. 0 = purely organic. Balance multiplier scales the M18 average balance.
A26: CAC (VND '000) \ Balance multiplier | B26: 1 | C26: 2 | D26: 3 | E26: 4 | F26: 5
A27: 0 | B27: =IF($A27>0,Unit_Economics!$D$15*B$26/$A27,"organic") -> organic | C27: =IF($A27>0,Unit_Economics!$D$15*C$26/$A27,"organic") -> organic | D27: =IF($A27>0,Unit_Economics!$D$15*D$26/$A27,"organic") -> organic | E27: =IF($A27>0,Unit_Economics!$D$15*E$26/$A27,"organic") -> organic | F27: =IF($A27>0,Unit_Economics!$D$15*F$26/$A27,"organic") -> organic
A28: 30 | B28: =IF($A28>0,Unit_Economics!$D$15*B$26/$A28,"organic") -> 0.25184046 | C28: =IF($A28>0,Unit_Economics!$D$15*C$26/$A28,"organic") -> 0.50368092 | D28: =IF($A28>0,Unit_Economics!$D$15*D$26/$A28,"organic") -> 0.75552138 | E28: =IF($A28>0,Unit_Economics!$D$15*E$26/$A28,"organic") -> 1.0073618 | F28: =IF($A28>0,Unit_Economics!$D$15*F$26/$A28,"organic") -> 1.2592023
A29: 60 | B29: =IF($A29>0,Unit_Economics!$D$15*B$26/$A29,"organic") -> 0.12592023 | C29: =IF($A29>0,Unit_Economics!$D$15*C$26/$A29,"organic") -> 0.25184046 | D29: =IF($A29>0,Unit_Economics!$D$15*D$26/$A29,"organic") -> 0.37776069 | E29: =IF($A29>0,Unit_Economics!$D$15*E$26/$A29,"organic") -> 0.50368092 | F29: =IF($A29>0,Unit_Economics!$D$15*F$26/$A29,"organic") -> 0.62960115
A30: 120 | B30: =IF($A30>0,Unit_Economics!$D$15*B$26/$A30,"organic") -> 0.062960115 | C30: =IF($A30>0,Unit_Economics!$D$15*C$26/$A30,"organic") -> 0.12592023 | D30: =IF($A30>0,Unit_Economics!$D$15*D$26/$A30,"organic") -> 0.18888034 | E30: =IF($A30>0,Unit_Economics!$D$15*E$26/$A30,"organic") -> 0.25184046 | F30: =IF($A30>0,Unit_Economics!$D$15*F$26/$A30,"organic") -> 0.31480057
A31: 200 | B31: =IF($A31>0,Unit_Economics!$D$15*B$26/$A31,"organic") -> 0.037776069 | C31: =IF($A31>0,Unit_Economics!$D$15*C$26/$A31,"organic") -> 0.075552138 | D31: =IF($A31>0,Unit_Economics!$D$15*D$26/$A31,"organic") -> 0.11332821 | E31: =IF($A31>0,Unit_Economics!$D$15*E$26/$A31,"organic") -> 0.15110428 | F31: =IF($A31>0,Unit_Economics!$D$15*F$26/$A31,"organic") -> 0.18888034
A32: Red = below the common 3x LTV / CAC threshold.

Sheet Assumptions
A1: Habitlock financial model: assumptions
A2: Blue = input (edit these). Black = formula. Yellow fill = key assumption that must be validated with Infina. All VND. Nothing here is Infina data unless Source says 'Deck'.
A3: Source key: Deck = taken from the Habitlock proposal; Illustrative = my placeholder, not evidence; Confirm = needs Infina / real data before anyone relies on it.
A5: Parameter | B5: Unit | C5: Conservative | D5: Base | E5: Aggressive | F5: Source | G5: Note
A6: Units
A7: VND per VND million | B7: VND | C7: =D7 -> 1000000 | D7: 1000000 | E7: =D7 -> 1000000 | F7: Constant
A8: VND per VND thousand | B8: VND | C8: =D8 -> 1000 | D8: 1000 | E8: =D8 -> 1000 | F8: Constant
A9: Market funnel (Deck sizing)
A10: Population aged 18-25 | B10: people | C10: =D10 -> 17000000 | D10: 17000000 | E10: =D10 -> 17000000 | F10: Deck | G10: Top-down estimate, no source in deck
A11: Interested in personal finance | B11: people | C11: =D11 -> 7000000 | D11: 7000000 | E11: =D11 -> 7000000 | F11: Deck
A12: Ready to save with the right tool | B12: people | C12: =D12 -> 3000000 | D12: 3000000 | E12: =D12 -> 3000000 | F12: Deck
A13: Acquisition and activation
A14: Cumulative users acquired by M18, % of 'ready' pool | B14: % | C14: 0.05 | D14: 0.1 | E14: 0.2 | F14: Illustrative | G14: Deck claims 20-30% (600-900K users). Aggressive = deck low end. Base is half of it.
A15: Acquired users who make a first deposit | B15: % | C15: 0.5 | D15: 0.6 | E15: 0.7 | F15: Illustrative
A16: CAC per activated user | B16: VND | C16: 200000 | D16: 120000 | E16: 80000 | F16: Illustrative | G16: Confirm with Infina's blended CAC
A17: Retention and balances
A18: Monthly churn of activated users (full exit) | B18: %/month | C18: 0.12 | D18: 0.08 | E18: 0.05 | F18: Illustrative | G18: Constant hazard for simplicity
A19: Deposit per active user per month | B19: VND | C19: 300000 | D19: 500000 | E19: 800000 | F19: Illustrative | G19: Badge Lv1/Lv2 floor is 100K/month (Deck)
A20: Partial withdrawals, % of AUM per month (before Pause & Reflect) | B20: %/month | C20: 0.06 | D20: 0.05 | E20: 0.04 | F20: Illustrative
A21: Share of partial withdrawals that are impulsive | B21: % | C21: =D21 -> 0.6 | D21: 0.6 | E21: =D21 -> 0.6 | F21: Illustrative | G21: Deck: >70% SAY impulsive spending is the main barrier. Self-report is not withdrawal data.
A22: Pause & Reflect: share of impulsive withdrawals cancelled | B22: % | C22: 0.1 | D22: 0.2 | E22: 0.35 | F22: Illustrative | G22: Core product hypothesis. Test it, do not assume it.
A23: Revenue to Infina (annual, % of AUM)
A24: Net take rate on savings AUM | B24: %/yr | C24: 0.003 | D24: 0.005 | E24: 0.007 | F24: Confirm | G24: Spread or commission Infina keeps. Biggest unknown in the model.
A25: Net take rate on fund AUM | B25: %/yr | C25: 0.005 | D25: 0.008 | E25: 0.01 | F25: Confirm | G25: Distribution fee share
A26: Incrementality: share of Habitlock AUM revenue that is truly new | B26: % | C26: 0.5 | D26: 0.7 | E26: 0.9 | F26: Illustrative | G26: Some users would have saved in Infina anyway. Bonus cost is NOT scaled by this.
A27: Fund share of AUM once AI / auto-invest is mature | B27: % | C27: 0.05 | D27: 0.1 | E27: 0.2 | F27: Illustrative | G27: Deck: auto-invest moves only 10-20% of savings, so this is capped by design
A28: Months to reach mature fund share after AI launch | B28: months | C28: =D28 -> 6 | D28: 6 | E28: =D28 -> 6 | F28: Illustrative
A29: Product timeline (months since launch; Deck roadmap assumes Jul start)
A30: Calendar month of launch (1=Jan) | B30: month | C30: =D30 -> 7 | D30: 7 | E30: =D30 -> 7 | F30: Deck | G30: Jul 2025 start
A31: Pause & Reflect live from month | B31: month | C31: =D31 -> 3 | D31: 3 | E31: =D31 -> 3 | F31: Deck | G31: Sep on the roadmap
A32: Streaks and badges live from month | B32: month | C32: =D32 -> 4 | D32: 4 | E32: =D32 -> 4 | F32: Deck | G32: Oct on the roadmap
A33: AI suggestions and auto-invest live from month | B33: month | C33: =D33 -> 5 | D33: 5 | E33: =D33 -> 5 | F33: Deck | G33: Nov on the roadmap
A34: Last month of deck Phase 3 (Nov-Dec) | B34: month | C34: =D34 -> 6 | D34: 6 | E34: =D34 -> 6 | F34: Deck
A35: Badges
A36: Active users who meet badge conditions | B36: % | C36: 0.5 | D36: 0.65 | E36: 0.8 | F36: Illustrative | G36: Streaks are hard. Not everyone qualifies.
A37: Eligible users (Lv5+) who adopt auto-invest | B37: % | C37: 0.1 | D37: 0.2 | E37: 0.3 | F37: Illustrative
A38: Costs
A39: One-off build, QA and compliance cost | B39: VND | C39: =D39 -> 1500000000 | D39: 1500000000 | E39: =D39 -> 1500000000 | F39: Illustrative | G39: Confirm: engineering + legal + design
A40: Months over which build cost is spent | B40: months | C40: =D40 -> 3 | D40: 3 | E40: =D40 -> 3 | F40: Illustrative
A41: Monthly run cost (PM, CS, ops, data) | B41: VND | C41: =D41 -> 120000000 | D41: 120000000 | E41: =D41 -> 120000000 | F41: Illustrative
...

Sheet Model_Cons
A1: Habitlock model, Conservative scenario
A2: All money in VND million unless stated. Months are counted from launch. Flows are monthly; stocks are end of month.
A3: Line item | B3: Unit | C3: 18M total | D3: M1 | E3: M2 | F3: M3 | G3: M4 | H3: M5 | I3: M6 | J3: M7 | K3: M8 | L3: M9 | M3: M10 | N3: M11 | O3: M12 | P3: M13 | Q3: M14 | R3: M15 | S3: M16 | T3: M17 | U3: M18
A4: Month since launch | B4: # | D4: 1 | E4: 2 | F4: 3 | G4: 4 | H4: 5 | I4: 6 | J4: 7 | K4: 8 | L4: 9 | M4: 10 | N4: 11 | O4: 12 | P4: 13 | Q4: 14 | R4: 15 | S4: 16 | T4: 17 | U4: 18
A5: Calendar month | B5: 1-12 | D5: =MOD(Assumptions!$C$30-1+D4-1,12)+1 -> 7 | E5: =MOD(Assumptions!$C$30-1+E4-1,12)+1 -> 8 | F5: =MOD(Assumptions!$C$30-1+F4-1,12)+1 -> 9 | G5: =MOD(Assumptions!$C$30-1+G4-1,12)+1 -> 10 | H5: =MOD(Assumptions!$C$30-1+H4-1,12)+1 -> 11 | I5: =MOD(Assumptions!$C$30-1+I4-1,12)+1 -> 12 | J5: =MOD(Assumptions!$C$30-1+J4-1,12)+1 -> 1 | K5: =MOD(Assumptions!$C$30-1+K4-1,12)+1 -> 2 | ... U5: =MOD(Assumptions!$C$30-1+U4-1,12)+1 -> 12
A6: Withdrawal seasonality | B6: x | D6: =INDEX(Assumptions!$C$57:$N$57,D5) -> 1 | E6: =INDEX(Assumptions!$C$57:$N$57,E5) -> 1 | F6: =INDEX(Assumptions!$C$57:$N$57,F5) -> 1 | G6: =INDEX(Assumptions!$C$57:$N$57,G5) -> 1 | H6: =INDEX(Assumptions!$C$57:$N$57,H5) -> 1 | I6: =INDEX(Assumptions!$C$57:$N$57,I5) -> 1.3 | J6: =INDEX(Assumptions!$C$57:$N$57,J5) -> 1.4 | K6: =INDEX(Assumptions!$C$57:$N$57,K5) -> 1.2 | ... U6: =INDEX(Assumptions!$C$57:$N$57,U5) -> 1.3
A7: Signup weight (normalised) | B7: % | D7: =INDEX(Assumptions!$C$61:$T$61,D4)/SUM(Assumptions!$C$61:$T$61) -> 0.020833333 | E7: =INDEX(Assumptions!$C$61:$T$61,E4)/SUM(Assumptions!$C$61:$T$61) -> 0.03125 | F7: =INDEX(Assumptions!$C$61:$T$61,F4)/SUM(Assumptions!$C$61:$T$61) -> 0.041666667 | G7: =INDEX(Assumptions!$C$61:$T$61,G4)/SUM(Assumptions!$C$61:$T$61) -> 0.052083333 | H7: =INDEX(Assumptions!$C$61:$T$61,H4)/SUM(Assumptions!$C$61:$T$61) -> 0.0625 | I7: =INDEX(Assumptions!$C$61:$T$61,I4)/SUM(Assumptions!$C$61:$T$61) -> 0.072916667 | J7: =INDEX(Assumptions!$C$61:$T$61,J4)/SUM(Assumptions!$C$61:$T$61) -> 0.072916667 | K7: =INDEX(Assumptions!$C$61:$T$61,K4)/SUM(Assumptions!$C$61:$T$61) -> 0.072916667 | ... U7: =INDEX(Assumptions!$C$61:$T$61,U4)/SUM(Assumptions!$C$61:$T$61) -> 0.041666667
A8: Funnel
A9: New users acquired | B9: users | C9: =SUM(D9:U9) -> 150000 | D9: =Assumptions!$C$14*Assumptions!$C$12*D7 -> 3125 | E9: =Assumptions!$C$14*Assumptions!$C$12*E7 -> 4687.5 | F9: =Assumptions!$C$14*Assumptions!$C$12*F7 -> 6250 | G9: =Assumptions!$C$14*Assumptions!$C$12*G7 -> 7812.5 | H9: =Assumptions!$C$14*Assumptions!$C$12*H7 -> 9375 | I9: =Assumptions!$C$14*Assumptions!$C$12*I7 -> 10937.5 | J9: =Assumptions!$C$14*Assumptions!$C$12*J7 -> 10937.5 | K9: =Assumptions!$C$14*Assumptions!$C$12*K7 -> 10937.5 | ... U9: =Assumptions!$C$14*Assumptions!$C$12*U7 -> 6250
A10: New activated users (first deposit) | B10: users | C10: =SUM(D10:U10) -> 75000 | D10: =D9*Assumptions!$C$15 -> 1562.5 | E10: =E9*Assumptions!$C$15 -> 2343.75 | F10: =F9*Assumptions!$C$15 -> 3125 | G10: =G9*Assumptions!$C$15 -> 3906.25 | H10: =H9*Assumptions!$C$15 -> 4687.5 | I10: =I9*Assumptions!$C$15 -> 5468.75 | J10: =J9*Assumptions!$C$15 -> 5468.75 | K10: =K9*Assumptions!$C$15 -> 5468.75 | ... U10: =U9*Assumptions!$C$15 -> 3125
A11: Active users, end of month | B11: users | D11: =SUM(D49:D66) -> 1562.5 | E11: =SUM(E49:E66) -> 3718.75 | F11: =SUM(F49:F66) -> 6397.5 | G11: =SUM(G49:G66) -> 9536.05 | H11: =SUM(H49:H66) -> 13079.224 | I11: =SUM(I49:I66) -> 16978.467 | J11: =SUM(J49:J66) -> 20409.801 | K11: =SUM(K49:K66) -> 23429.375 | ... U11: =SUM(U49:U66) -> 30693.461
A12: Users who exit in month | B12: users | C12: =SUM(D12:U12) -> 44306.539 | D12: =0 -> 0 | E12: =D11*Assumptions!$C$18 -> 187.5 | F12: =E11*Assumptions!$C$18 -> 446.25 | G12: =F11*Assumptions!$C$18 -> 767.7 | H12: =G11*Assumptions!$C$18 -> 1144.326 | I12: =H11*Assumptions!$C$18 -> 1569.5069 | J12: =I11*Assumptions!$C$18 -> 2037.4161 | K12: =J11*Assumptions!$C$18 -> 2449.1761 | L12: =K11*Assumptions!$C$18 -> 2811.525 | ... U12: =T11*Assumptions!$C$18 -> 3759.3355
A13: Cumulative users acquired | B13: users | D13: =D9 -> 3125 | E13: =D13+E9 -> 7812.5 | F13: =E13+F9 -> 14062.5 | G13: =F13+G9 -> 21875 | H13: =G13+H9 -> 31250 | I13: =H13+I9 -> 42187.5 | J13: =I13+J9 -> 53125 | K13: =J13+K9 -> 64062.5 | L13: =K13+L9 -> 75000 | ... U13: =T13+U9 -> 150000
A14: AUM
A15: Average balance per active user, start of month | B15: VND mn/user | D15: =IF(0>0,0/0,0) -> 0 | E15: =IF(D11>0,D21/D11,0) -> 0.3 | F15: =IF(E11>0,E21/E11,0) -> 0.40426891 | G15: =IF(F11>0,F21/F11,0) -> 0.49513161 | H15: =IF(G11>0,G21/G11,0) -> 0.57582462 | I15: =IF(H11>0,H21/H11,0) -> 0.64861605 | J15: =IF(I11>0,I21/I11,0) -> 0.70745875 | K15: =IF(J11>0,J21/J11,0) -> 0.77700397 | L15: =IF(K11>0,K21/K11,0) -> 0.85532725 | ... U15: =IF(T11>0,T21/T11,0) -> 1.5461409
A16: Gross deposits | B16: VND mn | C16: =SUM(D16:U16) -> 119974.39 | D16: =D11*Assumptions!$C$19/Assumptions!$C$7 -> 468.75 | E16: =E11*Assumptions!$C$19/Assumptions!$C$7 -> 1115.625 | F16: =F11*Assumptions!$C$19/Assumptions!$C$7 -> 1919.25 | G16: =G11*Assumptions!$C$19/Assumptions!$C$7 -> 2860.815 | H16: =H11*Assumptions!$C$19/Assumptions!$C$7 -> 3923.7672 | I16: =I11*Assumptions!$C$19/Assumptions!$C$7 -> 5093.5401 | J16: =J11*Assumptions!$C$19/Assumptions!$C$7 -> 6122.9403 | K16: =K11*Assumptions!$C$19/Assumptions!$C$7 -> 7028.8125 | ... U16: =U11*Assumptions!$C$19/Assumptions!$C$7 -> 9208.0382
A17: Exit withdrawals (churned users take full balance) | B17: VND mn | C17: =SUM(D17:U17) -> 49534.506 | D17: =D12*D15 -> 0 | E17: =E12*E15 -> 56.25 | F17: =F12*F15 -> 180.405 | G17: =G12*G15 -> 380.11254 | H17: =H12*H15 -> 658.93109 | I17: =I12*I15 -> 1018.0074 | J17: =J12*J15 -> 1441.3878 | K17: =K12*K15 -> 1903.0196 | ... U17: =U12*U15 -> 5812.4626
A18: Pause & Reflect live (1/0) | B18: flag | D18: =IF(D4>=Assumptions!$C$31,1,0) -> 0 | E18: =IF(E4>=Assumptions!$C$31,1,0) -> 0 | F18: =IF(F4>=Assumptions!$C$31,1,0) -> 1 | G18: =IF(G4>=Assumptions!$C$31,1,0) -> 1 | H18: =IF(H4>=Assumptions!$C$31,1,0) -> 1 | I18: =IF(I4>=Assumptions!$C$31,1,0) -> 1 | J18: =IF(J4>=Assumptions!$C$31,1,0) -> 1 | K18: =IF(K4>=Assumptions!$C$31,1,0) -> 1 | ... U18: =IF(U4>=Assumptions!$C$31,1,0) -> 1
A19: Partial withdrawal rate after Pause & Reflect | B19: %/month | D19: =Assumptions!$C$20*D6*(1-Assumptions!$C$21*Assumptions!$C$22*D18) -> 0.06 | E19: =Assumptions!$C$20*E6*(1-Assumptions!$C$21*Assumptions!$C$22*E18) -> 0.06 | F19: =Assumptions!$C$20*F6*(1-Assumptions!$C$21*Assumptions!$C$22*F18) -> 0.0564 | G19: =Assumptions!$C$20*G6*(1-Assumptions!$C$21*Assumptions!$C$22*G18) -> 0.0564 | H19: =Assumptions!$C$20*H6*(1-Assumptions!$C$21*Assumptions!$C$22*H18) -> 0.0564 | I19: =Assumptions!$C$20*I6*(1-Assumptions!$C$21*Assumptions!$C$22*I18) -> 0.07332 | J19: =Assumptions!$C$20*J6*(1-Assumptions!$C$21*Assumptions!$C$22*J18) -> 0.07896 | K19: =Assumptions!$C$20*K6*(1-Assumptions!$C$21*Assumptions!$C$22*K18) -> 0.06768 | ... U19: =Assumptions!$C$20*U6*(1-Assumptions!$C$21*Assumptions!$C$22*U18) -> 0.07332
A20: Partial withdrawals | B20: VND mn | C20: =SUM(D20:U20) -> 21732.362 | D20: =(0-D17)*D19 -> 0 | E20: =(D21-E17)*E19 -> 24.75 | F20: =(E21-F17)*F19 -> 74.615508 | G20: =(F21-G17)*G19 -> 157.21455 | H20: =(G21-H17)*H19 -> 272.5339 | I20: =(H21-I17)*I19 -> 547.36219 | J20: =(I21-J17)*J19 -> 834.62121 | K20: =(J21-K17)*K19 -> 944.50668 | L20: =(K21-L17)*L19 -> 994.6145 | ... U20: =(T21-U17)*U19 -> 3125.2449
A21: AUM, end of month | B21: VND mn | D21: =0+D16-D17-D20 -> 468.75 | E21: =D21+E16-E17-E20 -> 1503.375 | F21: =E21+F16-F17-F20 -> 3167.6045 | G21: =F21+G16-G17-G20 -> 5491.0924 | H21: =G21+H16-H17-H20 -> 8483.3946 | I21: =H21+I16-I17-I20 -> 12011.565 | J21: =I21+J16-J17-J20 -> 15858.496 | K21: =J21+K16-K17-K20 -> 20039.783 | L21: =K21+L16-L17-L20 -> 24466.374 | ... U21: =T21+U16-U17-U20 -> 48707.519
A22: Fund share of AUM | B22: % | D22: =IF(D4<Assumptions!$C$33,0,MIN(1,(D4-Assumptions!$C$33+1)/Assumptions!$C$28))*Assumptions!$C$27 -> 0 | E22: =IF(E4<Assumptions!$C$33,0,MIN(1,(E4-Assumptions!$C$33+1)/Assumptions!$C$28))*Assumptions!$C$27 -> 0 | F22: =IF(F4<Assumptions!$C$33,0,MIN(1,(F4-Assumptions!$C$33+1)/Assumptions!$C$28))*Assumptions!$C$27 -> 0 | G22: =IF(G4<Assumptions!$C$33,0,MIN(1,(G4-Assumptions!$C$33+1)/Assumptions!$C$28))*Assumptions!$C$27 -> 0 | H22: =IF(H4<Assumptions!$C$33,0,MIN(1,(H4-Assumptions!$C$33+1)/Assumptions!$C$28))*Assumptions!$C$27 -> 0.0083333333 | I22: =IF(I4<Assumptions!$C$33,0,MIN(1,(I4-Assumptions!$C$33+1)/Assumptions!$C$28))*Assumptions!$C$27 -> 0.016666667 | J22: =IF(J4<Assumptions!$C$33,0,MIN(1,(J4-Assumptions!$C$33+1)/Assumptions!$C$28))*Assumptions!$C$27 -> 0.025 | K22: =IF(K4<Assumptions!$C$33,0,MIN(1,(K4-Assumptions!$C$33+1)/Assumptions!$C$28))*Assumptions!$C$27 -> 0.033333333 | ... U22: =IF(U4<Assumptions!$C$33,0,MIN(1,(U4-Assumptions!$C$33+1)/Assumptions!$C$28))*Assumptions!$C$27 -> 0.05
A23: AUM in funds | B23: VND mn | D23: =D21*D22 -> 0 | E23: =E21*E22 -> 0 | F23: =F21*F22 -> 0 | G23: =G21*G22 -> 0 | H23: =H21*H22 -> 70.694955 | I23: =I21*I22 -> 200.19275 | J23: =J21*J22 -> 396.46241 | K23: =K21*K22 -> 667.99276 | ... U23: =U21*U22 -> 2435.3759
A24: AUM in savings | B24: VND mn | D24: =D21-D23 -> 468.75 | E24: =E21-E23 -> 1503.375 | F24: =F21-F23 -> 3167.6045 | G24: =G21-G23 -> 5491.0924 | H24: =H21-H23 -> 8412.6997 | I24: =I21-I23 -> 11811.372 | J24: =J21-J23 -> 15462.034 | K24: =K21-K23 -> 19371.79 | ... U24: =U21-U23 -> 46272.143
A25: Average AUM in month | B25: VND mn | D25: =(0+D21)/2 -> 234.375 | E25: =(D21+E21)/2 -> 986.0625 | F25: =(E21+F21)/2 -> 2335.4897 | G25: =(F21+G21)/2 -> 4329.3484 | H25: =(G21+H21)/2 -> 6987.2435 | I25: =(H21+I21)/2 -> 10247.48 | J25: =(I21+J21)/2 -> 13935.031 | K25: =(J21+K21)/2 -> 17949.14 | L25: =(K21+L21)/2 -> 22253.079 | ... U25: =(T21+U21)/2 -> 48572.354
A26: Counterfactual: same cohort without Pause & Reflect
A27: Avg balance per active user, no P&R | B27: VND mn/user | D27: =IF(0>0,0/0,0) -> 0 | E27: =IF(D11>0,D30/D11,0) -> 0.3 | F27: =IF(E11>0,E30/E11,0) -> 0.40426891 | G27: =IF(F11>0,F30/F11,0) -> 0.49438715 | H27: =IF(G11>0,G30/G11,0) -> 0.57435917 | I27: =IF(H11>0,H30/H11,0) -> 0.64640219 | J27: =IF(I11>0,I30/I11,0) -> 0.70401725 | K27: =IF(J11>0,J30/J11,0) -> 0.77208603 | L27: =IF(K11>0,K30/K11,0) -> 0.8492555 | ... U27: =IF(T11>0,T30/T11,0) -> 1.526508
A28: Exit withdrawals, no P&R | B28: VND mn | C28: =SUM(D28:U28) -> 49066.047 | D28: =D12*D27 -> 0 | E28: =E12*E27 -> 56.25 | F28: =F12*F27 -> 180.405 | G28: =G12*G27 -> 379.54102 | H28: =H12*H27 -> 657.25413 | I28: =I12*I27 -> 1014.5327 | J28: =J12*J27 -> 1434.3761 | K28: =K12*K27 -> 1890.9747 | ... U28: =U12*U27 -> 5738.6558
A29: Partial withdrawals, no P&R | B29: VND mn | C29: =SUM(D29:U29) -> 22899.337 | D29: =(0-D28)*Assumptions!$C$20*D6 -> 0 | E29: =(D30-E28)*Assumptions!$C$20*E6 -> 24.75 | F29: =(E30-F28)*Assumptions!$C$20*F6 -> 79.3782 | G29: =(F30-G28)*Assumptions!$C$20*G6 -> 166.99805 | H29: =(G30-H28)*Assumptions!$C$20*H6 -> 289.19182 | I29: =(H30-I28)*Assumptions!$C$20*I6 -> 580.31269 | J29: =(I30-J28)*Assumptions!$C$20*J6 -> 883.57565 | K29: =(J30-K28)*Assumptions!$C$20*K6 -> 998.43463 | L29: =(K30-L28)*Assumptions!$C$20*L6 -> 1050.5893 | ... U29: =(T30-U28)*Assumptions!$C$20*U6 -> 3282.5111
A30: AUM, no P&R | B30: VND mn | D30: =0+D16-D28-D29 -> 468.75 | E30: =D30+E16-E28-E29 -> 1503.375 | F30: =E30+F16-F28-F29 -> 3162.8418 | G30: =F30+G16-G28-G29 -> 5477.1177 | H30: =G30+H16-H28-H29 -> 8454.439 | I30: =H30+I16-I28-I29 -> 11953.134 | J30: =I30+J16-J28-J29 -> 15758.122 | K30: =J30+K16-K28-K29 -> 19897.526 | L30: =K30+L16-L28-L29 -> 24285.213 | ... U30: =T30+U16-U28-U29 -> 48009.003
A31: AUM retained thanks to Pause & Reflect | B31: VND mn | D31: =D21-D30 -> 0 | E31: =E21-E30 -> 0 | F31: =F21-F30 -> 4.762692 | G31: =G21-G30 -> 13.97467 | H31: =H21-H30 -> 28.955628 | I31: =I21-I30 -> 58.43145 | J31: =J21-J30 -> 100.37412 | K31: =K21-K30 -> 142.25718 | ... U31: =U21-U30 -> 698.51615
A32: P&L to Infina (incremental)
A33: Revenue on savings AUM | B33: VND mn | C33: =SUM(D33:U33) -> 104.28605 | D33: =D25*(1-D22)*Assumptions!$C$24/12 -> 0.05859375 | E33: =E25*(1-E22)*Assumptions!$C$24/12 -> 0.24651562 | F33: =F25*(1-F22)*Assumptions!$C$24/12 -> 0.58387244 | G33: =G25*(1-G22)*Assumptions!$C$24/12 -> 1.0823371 | H33: =H25*(1-H22)*Assumptions!$C$24/12 -> 1.7322541 | I33: =I25*(1-I22)*Assumptions!$C$24/12 -> 2.5191721 | J33: =J25*(1-J22)*Assumptions!$C$24/12 -> 3.3966638 | K33: =K25*(1-K22)*Assumptions!$C$24/12 -> 4.3377087 | ... U33: =U25*(1-U22)*Assumptions!$C$24/12 -> 11.535934
A34: Revenue on fund AUM | B34: VND mn | C34: =SUM(D34:U34) -> 8.3321305 | D34: =D25*D22*Assumptions!$C$25/12 -> 0 | E34: =E25*E22*Assumptions!$C$25/12 -> 0 | F34: =F25*F22*Assumptions!$C$25/12 -> 0 | G34: =G25*G22*Assumptions!$C$25/12 -> 0 | H34: =H25*H22*Assumptions!$C$25/12 -> 0.024261262 | I34: =I25*I22*Assumptions!$C$25/12 -> 0.071163055 | J34: =J25*J22*Assumptions!$C$25/12 -> 0.14515657 | K34: =K25*K22*Assumptions!$C$25/12 -> 0.24929361 | ... U34: =U25*U22*Assumptions!$C$25/12 -> 1.011924
A35: Gross revenue on Habitlock AUM | B35: VND mn | C35: =SUM(D35:U35) -> 112.61818 | D35: =D33+D34 -> 0.05859375 | E35: =E33+E34 -> 0.24651562 | F35: =F33+F34 -> 0.58387244 | G35: =G33+G34 -> 1.0823371 | H35: =H33+H34 -> 1.7565154 | I35: =I33+I34 -> 2.5903352 | J35: =J33+J34 -> 3.5418203 | K35: =K33+K34 -> 4.5870023 | ... U35: =U33+U34 -> 12.547858
A36: Incremental revenue (after incrementality) | B36: VND mn | C36: =SUM(D36:U36) -> 56.309089 | D36: =D35*Assumptions!$C$26 -> 0.029296875 | E36: =E35*Assumptions!$C$26 -> 0.12325781 | F36: =F35*Assumptions!$C$26 -> 0.29193622 | G36: =G35*Assumptions!$C$26 -> 0.54116856 | H36: =H35*Assumptions!$C$26 -> 0.87825769 | I36: =I35*Assumptions!$C$26 -> 1.2951676 | J36: =J35*Assumptions!$C$26 -> 1.7709102 | K36: =K35*Assumptions!$C$26 -> 2.2935012 | ... U36: =U35*Assumptions!$C$26 -> 6.273929
A37: Weighted average bonus rate (annual, savings AUM) | B37: %/yr | D37: =IF(D11>0,SUM(D71:D88)/D11,0) -> 0 | E37: =IF(E11>0,SUM(E71:E88)/E11,0) -> 0 | F37: =IF(F11>0,SUM(F71:F88)/F11,0) -> 0 | G37: =IF(G11>0,SUM(G71:G88)/G11,0) -> 0.00025 | H37: =IF(H11>0,SUM(H71:H88)/H11,0) -> 0.00041040179 | I37: =IF(I11>0,SUM(I71:I88)/I11,0) -> 0.00052821172 | J37: =IF(J11>0,SUM(J71:J88)/J11,0) -> 0.00071627971 | K37: =IF(K11>0,SUM(K71:K88)/K11,0) -> 0.00077825643 | ... U37: =IF(U11>0,SUM(U71:U88)/U11,0) -> 0.0010670685
A38: Bonus interest cost (paid on ALL Habitlock savings AUM) | B38: VND mn | C38: =SUM(D38:U38) -> 32.438328 | D38: =D25*(1-D22)*D37/12 -> 0 | E38: =E25*(1-E22)*E37/12 -> 0 | F38: =F25*(1-F22)*F37/12 -> 0 | G38: =G25*(1-G22)*G37/12 -> 0.090194759 | H38: =H25*(1-H22)*H37/12 -> 0.2369734 | I38: =I25*(1-I22)*I37/12 -> 0.44355208 | J38: =J25*(1-J22)*J37/12 -> 0.81098711 | K38: =K25*(1-K22)*K37/12 -> 1.1252832 | ... U38: =U25*(1-U22)*U37/12 -> 4.1032106
A39: Acquisition spend | B39: VND mn | C39: =SUM(D39:U39) -> 15000 | D39: =D10*Assumptions!$C$16/Assumptions!$C$7 -> 312.5 | E39: =E10*Assumptions!$C$16/Assumptions!$C$7 -> 468.75 | F39: =F10*Assumptions!$C$16/Assumptions!$C$7 -> 625 | G39: =G10*Assumptions!$C$16/Assumptions!$C$7 -> 781.25 | H39: =H10*Assumptions!$C$16/Assumptions!$C$7 -> 937.5 | I39: =I10*Assumptions!$C$16/Assumptions!$C$7 -> 1093.75 | J39: =J10*Assumptions!$C$16/Assumptions!$C$7 -> 1093.75 | K39: =K10*Assumptions!$C$16/Assumptions!$C$7 -> 1093.75 | ... U39: =U10*Assumptions!$C$16/Assumptions!$C$7 -> 625
A40: Build cost | B40: VND mn | C40: =SUM(D40:U40) -> 1500 | D40: =IF(D4<=Assumptions!$C$40,Assumptions!$C$39/Assumptions!$C$40/Assumptions!$C$7,0) -> 500 | E40: =IF(E4<=Assumptions!$C$40,Assumptions!$C$39/Assumptions!$C$40/Assumptions!$C$7,0) -> 500 | F40: =IF(F4<=Assumptions!$C$40,Assumptions!$C$39/Assumptions!$C$40/Assumptions!$C$7,0) -> 500 | G40: =IF(G4<=Assumptions!$C$40,Assumptions!$C$39/Assumptions!$C$40/Assumptions!$C$7,0) -> 0 | H40: =IF(H4<=Assumptions!$C$40,Assumptions!$C$39/Assumptions!$C$40/Assumptions!$C$7,0) -> 0 | I40: =IF(I4<=Assumptions!$C$40,Assumptions!$C$39/Assumptions!$C$40/Assumptions!$C$7,0) -> 0 | J40: =IF(J4<=Assumptions!$C$40,Assumptions!$C$39/Assumptions!$C$40/Assumptions!$C$7,0) -> 0 | K40: =IF(K4<=Assumptions!$C$40,Assumptions!$C$39/Assumptions!$C$40/Assumptions!$C$7,0) -> 0 | ... U40: =IF(U4<=Assumptions!$C$40,Assumptions!$C$39/Assumptions!$C$40/Assumptions!$C$7,0) -> 0
...

Sheet Model_Base
A1: Habitlock model, Base scenario
A2: All money in VND million unless stated. Months are counted from launch. Flows are monthly; stocks are end of month.
A3: Line item | B3: Unit | C3: 18M total | D3: M1 | E3: M2 | F3: M3 | G3: M4 | H3: M5 | I3: M6 | J3: M7 | K3: M8 | L3: M9 | M3: M10 | N3: M11 | O3: M12 | P3: M13 | Q3: M14 | R3: M15 | S3: M16 | T3: M17 | U3: M18
A4: Month since launch | B4: # | D4: 1 | E4: 2 | F4: 3 | G4: 4 | H4: 5 | I4: 6 | J4: 7 | K4: 8 | L4: 9 | M4: 10 | N4: 11 | O4: 12 | P4: 13 | Q4: 14 | R4: 15 | S4: 16 | T4: 17 | U4: 18
A5: Calendar month | B5: 1-12 | D5: =MOD(Assumptions!$D$30-1+D4-1,12)+1 -> 7 | E5: =MOD(Assumptions!$D$30-1+E4-1,12)+1 -> 8 | F5: =MOD(Assumptions!$D$30-1+F4-1,12)+1 -> 9 | G5: =MOD(Assumptions!$D$30-1+G4-1,12)+1 -> 10 | H5: =MOD(Assumptions!$D$30-1+H4-1,12)+1 -> 11 | I5: =MOD(Assumptions!$D$30-1+I4-1,12)+1 -> 12 | J5: =MOD(Assumptions!$D$30-1+J4-1,12)+1 -> 1 | K5: =MOD(Assumptions!$D$30-1+K4-1,12)+1 -> 2 | ... U5: =MOD(Assumptions!$D$30-1+U4-1,12)+1 -> 12
A6: Withdrawal seasonality | B6: x | D6: =INDEX(Assumptions!$C$57:$N$57,D5) -> 1 | E6: =INDEX(Assumptions!$C$57:$N$57,E5) -> 1 | F6: =INDEX(Assumptions!$C$57:$N$57,F5) -> 1 | G6: =INDEX(Assumptions!$C$57:$N$57,G5) -> 1 | H6: =INDEX(Assumptions!$C$57:$N$57,H5) -> 1 | I6: =INDEX(Assumptions!$C$57:$N$57,I5) -> 1.3 | J6: =INDEX(Assumptions!$C$57:$N$57,J5) -> 1.4 | K6: =INDEX(Assumptions!$C$57:$N$57,K5) -> 1.2 | ... U6: =INDEX(Assumptions!$C$57:$N$57,U5) -> 1.3
A7: Signup weight (normalised) | B7: % | D7: =INDEX(Assumptions!$C$61:$T$61,D4)/SUM(Assumptions!$C$61:$T$61) -> 0.020833333 | E7: =INDEX(Assumptions!$C$61:$T$61,E4)/SUM(Assumptions!$C$61:$T$61) -> 0.03125 | F7: =INDEX(Assumptions!$C$61:$T$61,F4)/SUM(Assumptions!$C$61:$T$61) -> 0.041666667 | G7: =INDEX(Assumptions!$C$61:$T$61,G4)/SUM(Assumptions!$C$61:$T$61) -> 0.052083333 | H7: =INDEX(Assumptions!$C$61:$T$61,H4)/SUM(Assumptions!$C$61:$T$61) -> 0.0625 | I7: =INDEX(Assumptions!$C$61:$T$61,I4)/SUM(Assumptions!$C$61:$T$61) -> 0.072916667 | J7: =INDEX(Assumptions!$C$61:$T$61,J4)/SUM(Assumptions!$C$61:$T$61) -> 0.072916667 | K7: =INDEX(Assumptions!$C$61:$T$61,K4)/SUM(Assumptions!$C$61:$T$61) -> 0.072916667 | ... U7: =INDEX(Assumptions!$C$61:$T$61,U4)/SUM(Assumptions!$C$61:$T$61) -> 0.041666667
A8: Funnel
A9: New users acquired | B9: users | C9: =SUM(D9:U9) -> 300000 | D9: =Assumptions!$D$14*Assumptions!$D$12*D7 -> 6250 | E9: =Assumptions!$D$14*Assumptions!$D$12*E7 -> 9375 | F9: =Assumptions!$D$14*Assumptions!$D$12*F7 -> 12500 | G9: =Assumptions!$D$14*Assumptions!$D$12*G7 -> 15625 | H9: =Assumptions!$D$14*Assumptions!$D$12*H7 -> 18750 | I9: =Assumptions!$D$14*Assumptions!$D$12*I7 -> 21875 | J9: =Assumptions!$D$14*Assumptions!$D$12*J7 -> 21875 | K9: =Assumptions!$D$14*Assumptions!$D$12*K7 -> 21875 | ... U9: =Assumptions!$D$14*Assumptions!$D$12*U7 -> 12500
A10: New activated users (first deposit) | B10: users | C10: =SUM(D10:U10) -> 180000 | D10: =D9*Assumptions!$D$15 -> 3750 | E10: =E9*Assumptions!$D$15 -> 5625 | F10: =F9*Assumptions!$D$15 -> 7500 | G10: =G9*Assumptions!$D$15 -> 9375 | H10: =H9*Assumptions!$D$15 -> 11250 | I10: =I9*Assumptions!$D$15 -> 13125 | J10: =J9*Assumptions!$D$15 -> 13125 | K10: =K9*Assumptions!$D$15 -> 13125 | ... U10: =U9*Assumptions!$D$15 -> 7500
A11: Active users, end of month | B11: users | D11: =SUM(D49:D66) -> 3750 | E11: =SUM(E49:E66) -> 9075 | F11: =SUM(F49:F66) -> 15849 | G11: =SUM(G49:G66) -> 23956.08 | H11: =SUM(H49:H66) -> 33289.594 | I11: =SUM(I49:I66) -> 43751.426 | J11: =SUM(J49:J66) -> 53376.312 | K11: =SUM(K49:K66) -> 62231.207 | ... U11: =SUM(U49:U66) -> 96828.953
A12: Users who exit in month | B12: users | C12: =SUM(D12:U12) -> 83171.047 | D12: =0 -> 0 | E12: =D11*Assumptions!$D$18 -> 300 | F12: =E11*Assumptions!$D$18 -> 726 | G12: =F11*Assumptions!$D$18 -> 1267.92 | H12: =G11*Assumptions!$D$18 -> 1916.4864 | I12: =H11*Assumptions!$D$18 -> 2663.1675 | J12: =I11*Assumptions!$D$18 -> 3500.1141 | K12: =J11*Assumptions!$D$18 -> 4270.105 | L12: =K11*Assumptions!$D$18 -> 4978.4966 | ... U12: =T11*Assumptions!$D$18 -> 7767.735
A13: Cumulative users acquired | B13: users | D13: =D9 -> 6250 | E13: =D13+E9 -> 15625 | F13: =E13+F9 -> 28125 | G13: =F13+G9 -> 43750 | H13: =G13+H9 -> 62500 | I13: =H13+I9 -> 84375 | J13: =I13+J9 -> 106250 | K13: =J13+K9 -> 128125 | L13: =K13+L9 -> 150000 | ... U13: =T13+U9 -> 300000
A14: AUM
A15: Average balance per active user, start of month | B15: VND mn/user | D15: =IF(0>0,0/0,0) -> 0 | E15: =IF(D11>0,D21/D11,0) -> 0.5 | F15: =IF(E11>0,E21/E11,0) -> 0.68057851 | G15: =IF(F11>0,F21/F11,0) -> 0.8427431 | H15: =IF(G11>0,G21/G11,0) -> 0.99037355 | I15: =IF(H11>0,H21/H11,0) -> 1.1268332 | J15: =IF(I11>0,I21/I11,0) -> 1.2436752 | K15: =IF(J11>0,J21/J11,0) -> 1.3800887 | L15: =IF(K11>0,K21/K11,0) -> 1.5315181 | ... U15: =IF(T11>0,T21/T11,0) -> 2.9704234
A16: Gross deposits | B16: VND mn | C16: =SUM(D16:U16) -> 568233.52 | D16: =D11*Assumptions!$D$19/Assumptions!$D$7 -> 1875 | E16: =E11*Assumptions!$D$19/Assumptions!$D$7 -> 4537.5 | F16: =F11*Assumptions!$D$19/Assumptions!$D$7 -> 7924.5 | G16: =G11*Assumptions!$D$19/Assumptions!$D$7 -> 11978.04 | H16: =H11*Assumptions!$D$19/Assumptions!$D$7 -> 16644.797 | I16: =I11*Assumptions!$D$19/Assumptions!$D$7 -> 21875.713 | J16: =J11*Assumptions!$D$19/Assumptions!$D$7 -> 26688.156 | K16: =K11*Assumptions!$D$19/Assumptions!$D$7 -> 31115.604 | ... U16: =U11*Assumptions!$D$19/Assumptions!$D$7 -> 48414.476
A17: Exit withdrawals (churned users take full balance) | B17: VND mn | C17: =SUM(D17:U17) -> 175435.65 | D17: =D12*D15 -> 0 | E17: =E12*E15 -> 150 | F17: =F12*F15 -> 494.1 | G17: =G12*G15 -> 1068.5308 | H17: =H12*H15 -> 1898.0374 | I17: =I12*I15 -> 3000.9456 | J17: =J12*J15 -> 4353.0053 | K17: =K12*K15 -> 5893.1238 | ... U17: =U12*U15 -> 23073.462
A18: Pause & Reflect live (1/0) | B18: flag | D18: =IF(D4>=Assumptions!$D$31,1,0) -> 0 | E18: =IF(E4>=Assumptions!$D$31,1,0) -> 0 | F18: =IF(F4>=Assumptions!$D$31,1,0) -> 1 | G18: =IF(G4>=Assumptions!$D$31,1,0) -> 1 | H18: =IF(H4>=Assumptions!$D$31,1,0) -> 1 | I18: =IF(I4>=Assumptions!$D$31,1,0) -> 1 | J18: =IF(J4>=Assumptions!$D$31,1,0) -> 1 | K18: =IF(K4>=Assumptions!$D$31,1,0) -> 1 | ... U18: =IF(U4>=Assumptions!$D$31,1,0) -> 1
A19: Partial withdrawal rate after Pause & Reflect | B19: %/month | D19: =Assumptions!$D$20*D6*(1-Assumptions!$D$21*Assumptions!$D$22*D18) -> 0.05 | E19: =Assumptions!$D$20*E6*(1-Assumptions!$D$21*Assumptions!$D$22*E18) -> 0.05 | F19: =Assumptions!$D$20*F6*(1-Assumptions!$D$21*Assumptions!$D$22*F18) -> 0.044 | G19: =Assumptions!$D$20*G6*(1-Assumptions!$D$21*Assumptions!$D$22*G18) -> 0.044 | H19: =Assumptions!$D$20*H6*(1-Assumptions!$D$21*Assumptions!$D$22*H18) -> 0.044 | I19: =Assumptions!$D$20*I6*(1-Assumptions!$D$21*Assumptions!$D$22*I18) -> 0.0572 | J19: =Assumptions!$D$20*J6*(1-Assumptions!$D$21*Assumptions!$D$22*J18) -> 0.0616 | K19: =Assumptions!$D$20*K6*(1-Assumptions!$D$21*Assumptions!$D$22*K18) -> 0.0528 | ... U19: =Assumptions!$D$20*U6*(1-Assumptions!$D$21*Assumptions!$D$22*U18) -> 0.0572
A20: Partial withdrawals | B20: VND mn | C20: =SUM(D20:U20) -> 94216.314 | D20: =(0-D17)*D19 -> 0 | E20: =(D21-E17)*E19 -> 86.25 | F20: =(E21-F17)*F19 -> 250.0146 | G20: =(F21-G17)*G19 -> 540.6766 | H20: =(G21-H17)*H19 -> 960.40694 | I20: =(H21-I17)*I19 -> 1974.022 | J20: =(I21-J17)*J19 -> 3083.6689 | K20: =(J21-K17)*K19 -> 3578.3048 | L20: =(K21-L17)*L19 -> 3858.0768 | ... U20: =(T21-U17)*U19 -> 15177.723
A21: AUM, end of month | B21: VND mn | D21: =0+D16-D17-D20 -> 1875 | E21: =D21+E16-E17-E20 -> 6176.25 | F21: =E21+F16-F17-F20 -> 13356.635 | G21: =F21+G16-G17-G20 -> 23725.468 | H21: =G21+H16-H17-H20 -> 37511.82 | I21: =H21+I16-I17-I20 -> 54412.566 | J21: =I21+J16-J17-J20 -> 73664.048 | K21: =J21+K16-K17-K20 -> 95308.223 | L21: =K21+L16-L17-L20 -> 119014.34 | ... U21: =T21+U16-U17-U20 -> 298581.56
A22: Fund share of AUM | B22: % | D22: =IF(D4<Assumptions!$D$33,0,MIN(1,(D4-Assumptions!$D$33+1)/Assumptions!$D$28))*Assumptions!$D$27 -> 0 | E22: =IF(E4<Assumptions!$D$33,0,MIN(1,(E4-Assumptions!$D$33+1)/Assumptions!$D$28))*Assumptions!$D$27 -> 0 | F22: =IF(F4<Assumptions!$D$33,0,MIN(1,(F4-Assumptions!$D$33+1)/Assumptions!$D$28))*Assumptions!$D$27 -> 0 | G22: =IF(G4<Assumptions!$D$33,0,MIN(1,(G4-Assumptions!$D$33+1)/Assumptions!$D$28))*Assumptions!$D$27 -> 0 | H22: =IF(H4<Assumptions!$D$33,0,MIN(1,(H4-Assumptions!$D$33+1)/Assumptions!$D$28))*Assumptions!$D$27 -> 0.016666667 | I22: =IF(I4<Assumptions!$D$33,0,MIN(1,(I4-Assumptions!$D$33+1)/Assumptions!$D$28))*Assumptions!$D$27 -> 0.033333333 | J22: =IF(J4<Assumptions!$D$33,0,MIN(1,(J4-Assumptions!$D$33+1)/Assumptions!$D$28))*Assumptions!$D$27 -> 0.05 | K22: =IF(K4<Assumptions!$D$33,0,MIN(1,(K4-Assumptions!$D$33+1)/Assumptions!$D$28))*Assumptions!$D$27 -> 0.066666667 | ... U22: =IF(U4<Assumptions!$D$33,0,MIN(1,(U4-Assumptions!$D$33+1)/Assumptions!$D$28))*Assumptions!$D$27 -> 0.1
A23: AUM in funds | B23: VND mn | D23: =D21*D22 -> 0 | E23: =E21*E22 -> 0 | F23: =F21*F22 -> 0 | G23: =G21*G22 -> 0 | H23: =H21*H22 -> 625.19701 | I23: =I21*I22 -> 1813.7522 | J23: =J21*J22 -> 3683.2024 | K23: =K21*K22 -> 6353.8815 | ... U23: =U21*U22 -> 29858.156
A24: AUM in savings | B24: VND mn | D24: =D21-D23 -> 1875 | E24: =E21-E23 -> 6176.25 | F24: =F21-F23 -> 13356.635 | G24: =G21-G23 -> 23725.468 | H24: =H21-H23 -> 36886.623 | I24: =I21-I23 -> 52598.814 | J24: =J21-J23 -> 69980.845 | K24: =K21-K23 -> 88954.341 | ... U24: =U21-U23 -> 268723.41
A25: Average AUM in month | B25: VND mn | D25: =(0+D21)/2 -> 937.5 | E25: =(D21+E21)/2 -> 4025.625 | F25: =(E21+F21)/2 -> 9766.4427 | G25: =(F21+G21)/2 -> 18541.052 | H25: =(G21+H21)/2 -> 30618.644 | I25: =(H21+I21)/2 -> 45962.193 | J25: =(I21+J21)/2 -> 64038.307 | K25: =(J21+K21)/2 -> 84486.135 | L25: =(K21+L21)/2 -> 107161.28 | ... U25: =(T21+U21)/2 -> 293499.92
A26: Counterfactual: same cohort without Pause & Reflect
A27: Avg balance per active user, no P&R | B27: VND mn/user | D27: =IF(0>0,0/0,0) -> 0 | E27: =IF(D11>0,D30/D11,0) -> 0.5 | F27: =IF(E11>0,E30/E11,0) -> 0.68057851 | G27: =IF(F11>0,F30/F11,0) -> 0.84059199 | H27: =IF(G11>0,G30/G11,0) -> 0.98605206 | I27: =IF(H11>0,H30/H11,0) -> 1.1201811 | J27: =IF(I11>0,I30/I11,0) -> 1.2331688 | K27: =IF(J11>0,J30/J11,0) -> 1.3648424 | L27: =IF(K11>0,K30/K11,0) -> 1.5123682 | ... U27: =IF(T11>0,T30/T11,0) -> 2.9009376
A28: Exit withdrawals, no P&R | B28: VND mn | C28: =SUM(D28:U28) -> 172355.97 | D28: =D12*D27 -> 0 | E28: =E12*E27 -> 150 | F28: =F12*F27 -> 494.1 | G28: =G12*G27 -> 1065.8034 | H28: =H12*H27 -> 1889.7554 | I28: =I12*I27 -> 2983.2299 | J28: =J12*J27 -> 4316.2314 | K28: =K12*K27 -> 5828.0201 | ... U28: =U12*U27 -> 22533.715
A29: Partial withdrawals, no P&R | B29: VND mn | C29: =SUM(D29:U29) -> 105169.31 | D29: =(0-D28)*Assumptions!$D$20*D6 -> 0 | E29: =(D30-E28)*Assumptions!$D$20*E6 -> 86.25 | F29: =(E30-F28)*Assumptions!$D$20*F6 -> 284.1075 | G29: =(F30-G28)*Assumptions!$D$20*G6 -> 612.83695 | H29: =(G30-H28)*Assumptions!$D$20*H6 -> 1086.6093 | I29: =(H30-I28)*Assumptions!$D$20*I6 -> 2229.9644 | J29: =(I30-J28)*Assumptions!$D$20*J6 -> 3474.5663 | K29: =(J30-K28)*Assumptions!$D$20*K6 -> 4021.3339 | L29: =(K30-L28)*Assumptions!$D$20*L6 -> 4329.359 | ... U29: =(T30-U28)*Assumptions!$D$20*U6 -> 16843.952
A30: AUM, no P&R | B30: VND mn | D30: =0+D16-D28-D29 -> 1875 | E30: =D30+E16-E28-E29 -> 6176.25 | F30: =E30+F16-F28-F29 -> 13322.542 | G30: =F30+G16-G28-G29 -> 23621.942 | H30: =G30+H16-H28-H29 -> 37290.374 | I30: =H30+I16-I28-I29 -> 53952.893 | J30: =I30+J16-J28-J29 -> 72850.251 | K30: =J30+K16-K28-K29 -> 94116.501 | L30: =K30+L16-L28-L29 -> 117446.68 | ... U30: =T30+U16-U28-U29 -> 290708.24
A31: AUM retained thanks to Pause & Reflect | B31: VND mn | D31: =D21-D30 -> 0 | E31: =E21-E30 -> 0 | F31: =F21-F30 -> 34.0929 | G31: =G21-G30 -> 103.52582 | H31: =H21-H30 -> 221.44615 | I31: =I21-I30 -> 459.6728 | J31: =J21-J30 -> 813.79636 | K31: =K21-K30 -> 1191.7217 | ... U31: =U21-U30 -> 7873.3198
A32: P&L to Infina (incremental)
A33: Revenue on savings AUM | B33: VND mn | C33: =SUM(D33:U33) -> 885.31651 | D33: =D25*(1-D22)*Assumptions!$D$24/12 -> 0.390625 | E33: =E25*(1-E22)*Assumptions!$D$24/12 -> 1.6773437 | F33: =F25*(1-F22)*Assumptions!$D$24/12 -> 4.0693511 | G33: =G25*(1-G22)*Assumptions!$D$24/12 -> 7.7254382 | H33: =H25*(1-H22)*Assumptions!$D$24/12 -> 12.545139 | I33: =I25*(1-I22)*Assumptions!$D$24/12 -> 18.51255 | J33: =J25*(1-J22)*Assumptions!$D$24/12 -> 25.348496 | K33: =K25*(1-K22)*Assumptions!$D$24/12 -> 32.855719 | ... U33: =U25*(1-U22)*Assumptions!$D$24/12 -> 110.06247
A34: Revenue on fund AUM | B34: VND mn | C34: =SUM(D34:U34) -> 144.98449 | D34: =D25*D22*Assumptions!$D$25/12 -> 0 | E34: =E25*E22*Assumptions!$D$25/12 -> 0 | F34: =F25*F22*Assumptions!$D$25/12 -> 0 | G34: =G25*G22*Assumptions!$D$25/12 -> 0 | H34: =H25*H22*Assumptions!$D$25/12 -> 0.34020716 | I34: =I25*I22*Assumptions!$D$25/12 -> 1.0213821 | J34: =J25*J22*Assumptions!$D$25/12 -> 2.1346102 | K34: =K25*K22*Assumptions!$D$25/12 -> 3.7549393 | ... U34: =U25*U22*Assumptions!$D$25/12 -> 19.566661
A35: Gross revenue on Habitlock AUM | B35: VND mn | C35: =SUM(D35:U35) -> 1030.301 | D35: =D33+D34 -> 0.390625 | E35: =E33+E34 -> 1.6773437 | F35: =F33+F34 -> 4.0693511 | G35: =G33+G34 -> 7.7254382 | H35: =H33+H34 -> 12.885346 | I35: =I33+I34 -> 19.533932 | J35: =J33+J34 -> 27.483107 | K35: =K33+K34 -> 36.610659 | ... U35: =U33+U34 -> 129.62913
A36: Incremental revenue (after incrementality) | B36: VND mn | C36: =SUM(D36:U36) -> 721.2107 | D36: =D35*Assumptions!$D$26 -> 0.2734375 | E36: =E35*Assumptions!$D$26 -> 1.1741406 | F36: =F35*Assumptions!$D$26 -> 2.8485458 | G36: =G35*Assumptions!$D$26 -> 5.4078067 | H36: =H35*Assumptions!$D$26 -> 9.0197423 | I36: =I35*Assumptions!$D$26 -> 13.673752 | J36: =J35*Assumptions!$D$26 -> 19.238175 | K36: =K35*Assumptions!$D$26 -> 25.627461 | ... U36: =U35*Assumptions!$D$26 -> 90.740391
A37: Weighted average bonus rate (annual, savings AUM) | B37: %/yr | D37: =IF(D11>0,SUM(D71:D88)/D11,0) -> 0 | E37: =IF(E11>0,SUM(E71:E88)/E11,0) -> 0 | F37: =IF(F11>0,SUM(F71:F88)/F11,0) -> 0 | G37: =IF(G11>0,SUM(G71:G88)/G11,0) -> 0.000325 | H37: =IF(H11>0,SUM(H71:H88)/H11,0) -> 0.00054016838 | I37: =IF(I11>0,SUM(I71:I88)/I11,0) -> 0.00070312315 | J37: =IF(J11>0,SUM(J71:J88)/J11,0) -> 0.00096881145 | K37: =IF(K11>0,SUM(K71:K88)/K11,0) -> 0.0010635301 | ... U37: =IF(U11>0,SUM(U71:U88)/U11,0) -> 0.001508751
A38: Bonus interest cost (paid on ALL Habitlock savings AUM) | B38: VND mn | C38: =SUM(D38:U38) -> 233.83508 | D38: =D25*(1-D22)*D37/12 -> 0 | E38: =E25*(1-E22)*E37/12 -> 0 | F38: =F25*(1-F22)*F37/12 -> 0 | G38: =G25*(1-G22)*G37/12 -> 0.50215348 | H38: =H25*(1-H22)*H37/12 -> 1.3552975 | I38: =I25*(1-I22)*I37/12 -> 2.6033205 | J38: =J25*(1-J22)*J37/12 -> 4.9115827 | K38: =K25*(1-K22)*K37/12 -> 6.9886095 | ... U38: =U25*(1-U22)*U37/12 -> 33.211371
A39: Acquisition spend | B39: VND mn | C39: =SUM(D39:U39) -> 21600 | D39: =D10*Assumptions!$D$16/Assumptions!$D$7 -> 450 | E39: =E10*Assumptions!$D$16/Assumptions!$D$7 -> 675 | F39: =F10*Assumptions!$D$16/Assumptions!$D$7 -> 900 | G39: =G10*Assumptions!$D$16/Assumptions!$D$7 -> 1125 | H39: =H10*Assumptions!$D$16/Assumptions!$D$7 -> 1350 | I39: =I10*Assumptions!$D$16/Assumptions!$D$7 -> 1575 | J39: =J10*Assumptions!$D$16/Assumptions!$D$7 -> 1575 | K39: =K10*Assumptions!$D$16/Assumptions!$D$7 -> 1575 | ... U39: =U10*Assumptions!$D$16/Assumptions!$D$7 -> 900
A40: Build cost | B40: VND mn | C40: =SUM(D40:U40) -> 1500 | D40: =IF(D4<=Assumptions!$D$40,Assumptions!$D$39/Assumptions!$D$40/Assumptions!$D$7,0) -> 500 | E40: =IF(E4<=Assumptions!$D$40,Assumptions!$D$39/Assumptions!$D$40/Assumptions!$D$7,0) -> 500 | F40: =IF(F4<=Assumptions!$D$40,Assumptions!$D$39/Assumptions!$D$40/Assumptions!$D$7,0) -> 500 | G40: =IF(G4<=Assumptions!$D$40,Assumptions!$D$39/Assumptions!$D$40/Assumptions!$D$7,0) -> 0 | H40: =IF(H4<=Assumptions!$D$40,Assumptions!$D$39/Assumptions!$D$40/Assumptions!$D$7,0) -> 0 | I40: =IF(I4<=Assumptions!$D$40,Assumptions!$D$39/Assumptions!$D$40/Assumptions!$D$7,0) -> 0 | J40: =IF(J4<=Assumptions!$D$40,Assumptions!$D$39/Assumptions!$D$40/Assumptions!$D$7,0) -> 0 | K40: =IF(K4<=Assumptions!$D$40,Assumptions!$D$39/Assumptions!$D$40/Assumptions!$D$7,0) -> 0 | ... U40: =IF(U4<=Assumptions!$D$40,Assumptions!$D$39/Assumptions!$D$40/Assumptions!$D$7,0) -> 0
...

Sheet Model_Aggr
A1: Habitlock model, Aggressive scenario
A2: All money in VND million unless stated. Months are counted from launch. Flows are monthly; stocks are end of month.
A3: Line item | B3: Unit | C3: 18M total | D3: M1 | E3: M2 | F3: M3 | G3: M4 | H3: M5 | I3: M6 | J3: M7 | K3: M8 | L3: M9 | M3: M10 | N3: M11 | O3: M12 | P3: M13 | Q3: M14 | R3: M15 | S3: M16 | T3: M17 | U3: M18
A4: Month since launch | B4: # | D4: 1 | E4: 2 | F4: 3 | G4: 4 | H4: 5 | I4: 6 | J4: 7 | K4: 8 | L4: 9 | M4: 10 | N4: 11 | O4: 12 | P4: 13 | Q4: 14 | R4: 15 | S4: 16 | T4: 17 | U4: 18
A5: Calendar month | B5: 1-12 | D5: =MOD(Assumptions!$E$30-1+D4-1,12)+1 -> 7 | E5: =MOD(Assumptions!$E$30-1+E4-1,12)+1 -> 8 | F5: =MOD(Assumptions!$E$30-1+F4-1,12)+1 -> 9 | G5: =MOD(Assumptions!$E$30-1+G4-1,12)+1 -> 10 | H5: =MOD(Assumptions!$E$30-1+H4-1,12)+1 -> 11 | I5: =MOD(Assumptions!$E$30-1+I4-1,12)+1 -> 12 | J5: =MOD(Assumptions!$E$30-1+J4-1,12)+1 -> 1 | K5: =MOD(Assumptions!$E$30-1+K4-1,12)+1 -> 2 | ... U5: =MOD(Assumptions!$E$30-1+U4-1,12)+1 -> 12
A6: Withdrawal seasonality | B6: x | D6: =INDEX(Assumptions!$C$57:$N$57,D5) -> 1 | E6: =INDEX(Assumptions!$C$57:$N$57,E5) -> 1 | F6: =INDEX(Assumptions!$C$57:$N$57,F5) -> 1 | G6: =INDEX(Assumptions!$C$57:$N$57,G5) -> 1 | H6: =INDEX(Assumptions!$C$57:$N$57,H5) -> 1 | I6: =INDEX(Assumptions!$C$57:$N$57,I5) -> 1.3 | J6: =INDEX(Assumptions!$C$57:$N$57,J5) -> 1.4 | K6: =INDEX(Assumptions!$C$57:$N$57,K5) -> 1.2 | ... U6: =INDEX(Assumptions!$C$57:$N$57,U5) -> 1.3
A7: Signup weight (normalised) | B7: % | D7: =INDEX(Assumptions!$C$61:$T$61,D4)/SUM(Assumptions!$C$61:$T$61) -> 0.020833333 | E7: =INDEX(Assumptions!$C$61:$T$61,E4)/SUM(Assumptions!$C$61:$T$61) -> 0.03125 | F7: =INDEX(Assumptions!$C$61:$T$61,F4)/SUM(Assumptions!$C$61:$T$61) -> 0.041666667 | G7: =INDEX(Assumptions!$C$61:$T$61,G4)/SUM(Assumptions!$C$61:$T$61) -> 0.052083333 | H7: =INDEX(Assumptions!$C$61:$T$61,H4)/SUM(Assumptions!$C$61:$T$61) -> 0.0625 | I7: =INDEX(Assumptions!$C$61:$T$61,I4)/SUM(Assumptions!$C$61:$T$61) -> 0.072916667 | J7: =INDEX(Assumptions!$C$61:$T$61,J4)/SUM(Assumptions!$C$61:$T$61) -> 0.072916667 | K7: =INDEX(Assumptions!$C$61:$T$61,K4)/SUM(Assumptions!$C$61:$T$61) -> 0.072916667 | ... U7: =INDEX(Assumptions!$C$61:$T$61,U4)/SUM(Assumptions!$C$61:$T$61) -> 0.041666667
A8: Funnel
A9: New users acquired | B9: users | C9: =SUM(D9:U9) -> 600000 | D9: =Assumptions!$E$14*Assumptions!$E$12*D7 -> 12500 | E9: =Assumptions!$E$14*Assumptions!$E$12*E7 -> 18750 | F9: =Assumptions!$E$14*Assumptions!$E$12*F7 -> 25000 | G9: =Assumptions!$E$14*Assumptions!$E$12*G7 -> 31250 | H9: =Assumptions!$E$14*Assumptions!$E$12*H7 -> 37500 | I9: =Assumptions!$E$14*Assumptions!$E$12*I7 -> 43750 | J9: =Assumptions!$E$14*Assumptions!$E$12*J7 -> 43750 | K9: =Assumptions!$E$14*Assumptions!$E$12*K7 -> 43750 | ... U9: =Assumptions!$E$14*Assumptions!$E$12*U7 -> 25000
A10: New activated users (first deposit) | B10: users | C10: =SUM(D10:U10) -> 420000 | D10: =D9*Assumptions!$E$15 -> 8750 | E10: =E9*Assumptions!$E$15 -> 13125 | F10: =F9*Assumptions!$E$15 -> 17500 | G10: =G9*Assumptions!$E$15 -> 21875 | H10: =H9*Assumptions!$E$15 -> 26250 | I10: =I9*Assumptions!$E$15 -> 30625 | J10: =J9*Assumptions!$E$15 -> 30625 | K10: =K9*Assumptions!$E$15 -> 30625 | ... U10: =U9*Assumptions!$E$15 -> 17500
A11: Active users, end of month | B11: users | D11: =SUM(D49:D66) -> 8750 | E11: =SUM(E49:E66) -> 21437.5 | F11: =SUM(F49:F66) -> 37865.625 | G11: =SUM(G49:G66) -> 57847.344 | H11: =SUM(H49:H66) -> 81204.977 | I11: =SUM(I49:I66) -> 107769.73 | J11: =SUM(J49:J66) -> 133006.24 | K11: =SUM(K49:K66) -> 156980.93 | ... U11: =SUM(U49:U66) -> 281987.78
A12: Users who exit in month | B12: users | C12: =SUM(D12:U12) -> 138012.22 | D12: =0 -> 0 | E12: =D11*Assumptions!$E$18 -> 437.5 | F12: =E11*Assumptions!$E$18 -> 1071.875 | G12: =F11*Assumptions!$E$18 -> 1893.2812 | H12: =G11*Assumptions!$E$18 -> 2892.3672 | I12: =H11*Assumptions!$E$18 -> 4060.2488 | J12: =I11*Assumptions!$E$18 -> 5388.4864 | K12: =J11*Assumptions!$E$18 -> 6650.3121 | L12: =K11*Assumptions!$E$18 -> 7849.0465 | ... U12: =T11*Assumptions!$E$18 -> 13920.409
A13: Cumulative users acquired | B13: users | D13: =D9 -> 12500 | E13: =D13+E9 -> 31250 | F13: =E13+F9 -> 56250 | G13: =F13+G9 -> 87500 | H13: =G13+H9 -> 125000 | I13: =H13+I9 -> 168750 | J13: =I13+J9 -> 212500 | K13: =J13+K9 -> 256250 | L13: =K13+L9 -> 300000 | ... U13: =T13+U9 -> 600000
A14: AUM
